Workbook
Name UPDATE: 'Data Sheet'!$E$1

Sheet Input Sheet
B3: company description | D3: ITC Limited is an Indian conglomerate, headquartered in Kolkata. It has a presence across six business segments, namely FMCG, agribusiness, information technology, paper products, and packaging. It generates a plurality of its revenue from tobacco products. In terms of market capitalization, ITC is the second-largest FMCG company in India and the third-largest tobacco company in the world. It employs 36,500 people at more than 60 locations across India.

Sheet Teaser
B2: ='Data Sheet'!B1&" - "&"One Page Profile" -> ITC LTD - One Page Profile
C4: ='Input Sheet'!D3 -> ITC Limited is an Indian conglomerate, headquartered in Kolkata. It has a presence across six business segments, namely FMCG, agribusiness, information technology, paper products, and packaging. It generates a plurality of its revenue from tobacco products. In terms of market capitalization, ITC is the second-largest FMCG company in India and the third-largest tobacco company in the world. It employs 36,500 people at more than 60 locations across India.
B5: INR (Crs)
B6: Key Financial Metrics | C6: ='Profit & Loss'!E3 -> 43555 | D6: ='Profit & Loss'!F3 -> 43921 | E6: ='Profit & Loss'!G3 -> 44286 | F6: ='Profit & Loss'!H3 -> 44651 | G6: ='Profit & Loss'!I3 -> 45016 | I6: Share price - 5Y
B8: Total Sales | C8: ='Profit & Loss'!E4 -> 48339.58 | D8: ='Profit & Loss'!F4 -> 49387.7 | E8: ='Profit & Loss'!G4 -> 49257.45 | F8: ='Profit & Loss'!H4 -> 60644.54 | G8: ='Profit & Loss'!I4 -> 70919.03
B9: Sales Growth (Y-O-Y) | C9: ='Profit & Loss'!E27 -> 0.11256063 | D9: ='Profit & Loss'!F27 -> 0.021682439 | E9: ='Profit & Loss'!G27 -> -0.0026372963 | F9: ='Profit & Loss'!H27 -> 0.23117498 | G9: ='Profit & Loss'!I27 -> 0.16942152
B10: Growth Profit Margin (%) | C10: ='Profit & Loss'!E30 -> 0.57706604 | D10: ='Profit & Loss'!F30 -> 0.5658662 | E10: ='Profit & Loss'!G30 -> 0.51867748 | F10: ='Profit & Loss'!H30 -> 0.49650026 | G10: ='Profit & Loss'!I30 -> 0.53068887
B11: EBITDA Margins (%) | C11: ='Profit & Loss'!E31 -> 0.38348265 | D11: ='Profit & Loss'!F31 -> 0.39166716 | E11: ='Profit & Loss'!G31 -> 0.34644059 | F11: ='Profit & Loss'!H31 -> 0.34006606 | G11: ='Profit & Loss'!I31 -> 0.36244517
B12: EBIT Margins (%) | C12: ='Profit & Loss'!E32 -> 0.354591 | D12: ='Profit & Loss'!F32 -> 0.35836109 | E12: ='Profit & Loss'!G32 -> 0.31303265 | F12: ='Profit & Loss'!H32 -> 0.31149944 | G12: ='Profit & Loss'!I32 -> 0.33693707
B13: Net Margins (%) | C13: ='Profit & Loss'!E33 -> 0.2604973 | D13: ='Profit & Loss'!F33 -> 0.30991988 | E13: ='Profit & Loss'!G33 -> 0.26719187 | F13: ='Profit & Loss'!H33 -> 0.25134431 | G13: ='Profit & Loss'!I33 -> 0.27061368
B14: Earning per Share (in Rs) | C14: ='Profit & Loss'!E13 -> 10.272242 | D14: ='Profit & Loss'!F13 -> 12.451986 | E14: ='Profit & Loss'!G13 -> 10.692505 | F14: ='Profit & Loss'!H13 -> 12.368976 | G14: ='Profit & Loss'!I13 -> 15.442276
B15: EPS Growth (Y-O-Y) | C15: ='Profit & Loss'!E36 -> 0.11226415 | D15: ='Profit & Loss'!F36 -> 0.21219753 | E15: ='Profit & Loss'!G36 -> -0.14130126 | F15: ='Profit & Loss'!H36 -> 0.15678939 | G15: ='Profit & Loss'!I36 -> 0.2484684
B16: Dividend per Share (in Rs) | C16: ='Profit & Loss'!E38 -> 5.7500041 | D16: ='Profit & Loss'!F38 -> 10.149998 | E16: ='Profit & Loss'!G38 -> 10.75 | F16: ='Profit & Loss'!H38 -> 11.500004 | G16: ='Profit & Loss'!I38 -> 15.5
B17: DPS Growth (Y-O-Y) | C17: ='Profit & Loss'!E39 -> 0.11650645 | D17: ='Profit & Loss'!F39 -> 0.76521571 | E17: ='Profit & Loss'!G39 -> 0.059113555 | F17: ='Profit & Loss'!H39 -> 0.069767819 | G17: ='Profit & Loss'!I39 -> 0.34782561
B19: Key Financial Metrics | C19: =C6 -> 43555 | D19: =D6 -> 43921 | E19: =E6 -> 44286 | F19: =F6 -> 44651 | G19: =G6 -> 45016 | I19: Volumes - 5Y
B21: Price to Earnings | C21: ='Profit & Loss'!E14 -> 27.12553 | D21: ='Profit & Loss'!F14 -> 12.925649 | E21: ='Profit & Loss'!G14 -> 19.155475 | F21: ='Profit & Loss'!H14 -> 18.995914 | G21: ='Profit & Loss'!I14 -> 23.2796
B22: EV/EBITDA | C22: ='Profit & Loss'!E48 -> 18.202942 | D22: ='Profit & Loss'!F48 -> 9.8659847 | E22: ='Profit & Loss'!G48 -> 14.516487 | F22: ='Profit & Loss'!H48 -> 13.826369 | G22: ='Profit & Loss'!I48 -> 17.203375
B23: EV / Sales | C23: ='Profit & Loss'!E49 -> 6.9805125 | D23: ='Profit & Loss'!F49 -> 3.8641822 | E23: ='Profit & Loss'!G49 -> 5.0291002 | F23: ='Profit & Loss'!H49 -> 4.7018788 | G23: ='Profit & Loss'!I49 -> 6.2352802
B24: Price to Book value | C24: ='Profit & Loss'!E51 -> 5.7056151 | D24: ='Profit & Loss'!F51 -> 2.9237557 | E24: ='Profit & Loss'!G51 -> 4.1049142 | F24: ='Profit & Loss'!H51 -> 4.565538 | G24: ='Profit & Loss'!I51 -> 6.3943079
B25: Return On Equity | C25: 0.21 | D25: 0.23 | E25: 0.24 | F25: 0.24 | G25: 0.28
B26: Return on Capital Employed (%) | C26: 0.23 | D26: 0.22 | E26: 0.24 | F26: 0.28 | G26: 0
B28: Top 10 Shareholders | E28: =Sheet3!K63 -> N. Share (in Crs) | F28: =Sheet3!J63 -> Shareholding (%) | G28: =Sheet3!L63 -> Market value (in Crs) | I28: Shareholding Pattern
B29: =Sheet3!H64 -> Tobacco Manufacturers (India) Limited | E29: =Sheet3!K64 -> 222.84959 | F29: =Sheet3!J64 -> 17.79 | G29: =Sheet3!L64 -> 101062.29
B30: =Sheet3!H65 -> Life Insurance Corporation of India | E30: =Sheet3!K65 -> 198.58072 | F30: =Sheet3!J65 -> 15.86 | G30: =Sheet3!L65 -> 90056.358
B31: =Sheet3!H66 -> Specified Undertaking of the Unit Trust of India | E31: =Sheet3!K66 -> 97.453143 | F31: =Sheet3!J66 -> 7.78 | G31: =Sheet3!L66 -> 44195
B32: =Sheet3!H67 -> Myddleton Investment Company Limited | E32: =Sheet3!K67 -> 48.631194 | F32: =Sheet3!J67 -> 3.88 | G32: =Sheet3!L67 -> 22054.246
B33: =Sheet3!H68 -> SBI Mutual Funds | E33: =Sheet3!K68 -> 40.798409 | F33: =Sheet3!J68 -> 3.26 | G33: =Sheet3!L68 -> 18502.079
B34: =Sheet3!H69 -> QIB - Insurance Company Registered | E34: =Sheet3!K69 -> 33.990466 | F34: =Sheet3!J69 -> 2.71 | G34: =Sheet3!L69 -> 15414.676
B35: =Sheet3!H70 -> ICICI Prudential Mutual Funds | E35: =Sheet3!K70 -> 28.535049 | F35: =Sheet3!J70 -> 2.28 | G35: =Sheet3!L70 -> 12940.645
B36: =Sheet3!H71 -> GQG Partners Emerging Markets Equity Fund | E36: =Sheet3!K71 -> 26.34344 | F36: =Sheet3!J71 -> 2.1 | G36: =Sheet3!L71 -> 11946.75
B37: =Sheet3!H72 -> General Insurance Corporation of India | E37: =Sheet3!K72 -> 21.708551 | F37: =Sheet3!J72 -> 1.73 | G37: =Sheet3!L72 -> 9844.8278
B38: =Sheet3!H73 -> Goldman Sachs Trust II | E38: =Sheet3!K73 -> 20.70918 | F38: =Sheet3!J73 -> 1.65 | G38: =Sheet3!L73 -> 9391.6129
B40: Top 10 Shareholders | E40: Designation | F40: Remuneration | G40: X of Median Salary | I40: Capital Structure
B42: S Puri | E42: CMD | F42: 16.31 | G42: 326:1 | I42: Share Price as on XXX | M42: ='Data Sheet'!B8 -> 340.25
B43: N Anand | E43: Executive Director(ED) | F43: 8.19 | G43: 144:1 | I43: Number of Shares o/s | M43: ='Data Sheet'!B6 -> 1252.8958
B44: S Dutta | E44: ED & CFO | F44: 2 | G44: 88:1 | I44: Market Capitalization | M44: =M43*M42 -> 426297.81
B45: B Sumant | E45: ED | F45: 7.58 | G45: 152:1 | I45: Less: Cash & Equivalents | M45: ='Data Sheet'!I69*-1 -> -4880.19
I46: Add: Total Debt | M46: ='Data Sheet'!I59 -> 306.04
I47: Add: Minority Interest | M47: 383.53
I48: Enterprise Value | M48: 529526
...

Sheet Profit & Loss
A1: ='Data Sheet'!B1 -> ITC LTD | H1: =UPDATE | M1: SCREENER.IN
A3: Narration | B3: ='Data Sheet'!B16 -> 42460 | C3: ='Data Sheet'!C16 -> 42825 | D3: ='Data Sheet'!D16 -> 43190 | E3: ='Data Sheet'!E16 -> 43555 | F3: ='Data Sheet'!F16 -> 43921 | G3: ='Data Sheet'!G16 -> 44286 | H3: ='Data Sheet'!H16 -> 44651 | I3: ='Data Sheet'!I16 -> 45016 | ... K3: ='Data Sheet'!K16 -> 45747 | L3: Trailing | M3: Best Case | N3: Worst Case
A4: Sales | B4: ='Data Sheet'!B17 -> 39192.1 | C4: ='Data Sheet'!C17 -> 42767.6 | D4: ='Data Sheet'!D17 -> 43448.94 | E4: ='Data Sheet'!E17 -> 48339.58 | F4: ='Data Sheet'!F17 -> 49387.7 | G4: ='Data Sheet'!G17 -> 49257.45 | H4: ='Data Sheet'!H17 -> 60644.54 | I4: ='Data Sheet'!I17 -> 70919.03 | ... K4: ='Data Sheet'!K17 -> 75323.34 | L4: =SUM(Quarters!H4:K4) -> 78551.59 | M4: =$K4+M23*K4 -> 83518.968 | N4: =$K4+N23*L4 -> 81209.036
A5: Expenses | B5: =SUM('Data Sheet'!B18,'Data Sheet'!B20:B24, -1*'Data Sheet'!B19) -> 24660.61 | C5: =SUM('Data Sheet'!C18,'Data Sheet'!C20:C24, -1*'Data Sheet'!C19) -> 27298.09 | D5: =SUM('Data Sheet'!D18,'Data Sheet'!D20:D24, -1*'Data Sheet'!D19) -> 26928.35 | E5: =SUM('Data Sheet'!E18,'Data Sheet'!E20:E24, -1*'Data Sheet'!E19) -> 29802.19 | F5: =SUM('Data Sheet'!F18,'Data Sheet'!F20:F24, -1*'Data Sheet'!F19) -> 30044.16 | G5: =SUM('Data Sheet'!G18,'Data Sheet'!G20:G24, -1*'Data Sheet'!G19) -> 32192.67 | H5: =SUM('Data Sheet'!H18,'Data Sheet'!H20:H24, -1*'Data Sheet'!H19) -> 40021.39 | I5: =SUM('Data Sheet'!I18,'Data Sheet'!I20:I24, -1*'Data Sheet'!I19) -> 45214.77 | ... K5: =SUM('Data Sheet'!K18,'Data Sheet'!K20:K24, -1*'Data Sheet'!K19) -> 49483.89 | L5: =SUM(Quarters!H5:K5) -> 52159.14 | M5: =M4-M6 -> 53597.014 | N5: =N4-N6 -> 53923.714
A6: Operating Profit | B6: =B4-B5 -> 14531.49 | C6: =C4-C5 -> 15469.51 | D6: =D4-D5 -> 16520.59 | E6: =E4-E5 -> 18537.39 | F6: =F4-F5 -> 19343.54 | G6: =G4-G5 -> 17064.78 | H6: =H4-H5 -> 20623.15 | I6: =I4-I5 -> 25704.26 | ... K6: =K4-K5 -> 25839.45 | L6: =SUM(Quarters!H6:K6) -> 26392.45 | M6: =M4*M24 -> 29921.955 | N6: =N4*N24 -> 27285.322
A7: Other Income | B7: ='Data Sheet'!B25 -> 1483.11 | C7: ='Data Sheet'!C25 -> 1758.63 | D7: ='Data Sheet'!D25 -> 2239.81 | E7: ='Data Sheet'!E25 -> 2080.44 | F7: ='Data Sheet'!F25 -> 2417.32 | G7: ='Data Sheet'!G25 -> 2576.95 | H7: ='Data Sheet'!H25 -> 1909.72 | I7: ='Data Sheet'!I25 -> 2097.64 | ... K7: ='Data Sheet'!K25 -> 17794.88 | L7: =SUM(Quarters!H7:K7) -> 17684.49 | M7: 0 | N7: 0
A8: Depreciation | B8: ='Data Sheet'!B26 -> 1077.4 | C8: ='Data Sheet'!C26 -> 1152.79 | D8: ='Data Sheet'!D26 -> 1236.28 | E8: ='Data Sheet'!E26 -> 1396.61 | F8: ='Data Sheet'!F26 -> 1644.91 | G8: ='Data Sheet'!G26 -> 1645.59 | H8: ='Data Sheet'!H26 -> 1732.41 | I8: ='Data Sheet'!I26 -> 1809.01 | ... K8: ='Data Sheet'!K26 -> 1646.32 | L8: =SUM(Quarters!H8:K8) -> 1684.77 | M8: =+$L8 -> 1684.77 | N8: =+$L8 -> 1684.77
A9: Interest | B9: ='Data Sheet'!B27 -> 78.13 | C9: ='Data Sheet'!C27 -> 49.03 | D9: ='Data Sheet'!D27 -> 115.01 | E9: ='Data Sheet'!E27 -> 71.4 | F9: ='Data Sheet'!F27 -> 81.38 | G9: ='Data Sheet'!G27 -> 57.97 | H9: ='Data Sheet'!H27 -> 59.99 | I9: ='Data Sheet'!I27 -> 77.77 | ... K9: ='Data Sheet'!K27 -> 45.06 | L9: =SUM(Quarters!H9:K9) -> 57.25 | M9: =+$L9 -> 57.25 | N9: =+$L9 -> 57.25
A10: Profit before tax | B10: ='Data Sheet'!B28 -> 14859.07 | C10: ='Data Sheet'!C28 -> 16026.32 | D10: ='Data Sheet'!D28 -> 17409.11 | E10: ='Data Sheet'!E28 -> 19149.82 | F10: ='Data Sheet'!F28 -> 20034.57 | G10: ='Data Sheet'!G28 -> 17938.17 | H10: ='Data Sheet'!H28 -> 20740.47 | I10: ='Data Sheet'!I28 -> 25915.12 | ... K10: ='Data Sheet'!K28 -> 41942.95 | L10: =SUM(Quarters!H10:K10) -> 42334.92 | M10: =M6+M7-SUM(M8:M9) -> 28179.935 | N10: =N6+N7-SUM(N8:N9) -> 25543.302
A11: Tax | B11: ='Data Sheet'!B29 -> 5358.21 | C11: ='Data Sheet'!C29 -> 5549.09 | D11: ='Data Sheet'!D29 -> 5916.43 | E11: ='Data Sheet'!E29 -> 6313.92 | F11: ='Data Sheet'!F29 -> 4441.79 | G11: ='Data Sheet'!G29 -> 4555.29 | H11: ='Data Sheet'!H29 -> 5237.34 | I11: ='Data Sheet'!I29 -> 6438.4 | ... K11: ='Data Sheet'!K29 -> 6890.47 | L11: =SUM(Quarters!H11:K11) -> 6983.9 | M11: =IF($L10>0,$L11/$L10,0) -> 0.16496783 | N11: =IF($L10>0,$L11/$L10,0) -> 0.16496783
A12: Net profit | B12: ='Data Sheet'!B30 -> 9344.45 | C12: ='Data Sheet'!C30 -> 10289.44 | D12: ='Data Sheet'!D30 -> 11271.2 | E12: ='Data Sheet'!E30 -> 12592.33 | F12: ='Data Sheet'!F30 -> 15306.23 | G12: ='Data Sheet'!G30 -> 13161.19 | H12: ='Data Sheet'!H30 -> 15242.66 | I12: ='Data Sheet'!I30 -> 19191.66 | ... K12: ='Data Sheet'!K30 -> 34746.63 | L12: =SUM(Quarters!H12:K12) -> 35032.48 | M12: =M10-M11*M10 -> 23531.152 | N12: =N10-N11*N10 -> 21329.479
A13: EPS | B13: =IF('Data Sheet'!B93>0,B12/'Data Sheet'!B93,0) -> 7.7413676 | C13: =IF('Data Sheet'!C93>0,C12/'Data Sheet'!C93,0) -> 8.4704875 | D13: =IF('Data Sheet'!D93>0,D12/'Data Sheet'!D93,0) -> 9.2354334 | E13: =IF('Data Sheet'!E93>0,E12/'Data Sheet'!E93,0) -> 10.272242 | F13: =IF('Data Sheet'!F93>0,F12/'Data Sheet'!F93,0) -> 12.451986 | G13: =IF('Data Sheet'!G93>0,G12/'Data Sheet'!G93,0) -> 10.692505 | H13: =IF('Data Sheet'!H93>0,H12/'Data Sheet'!H93,0) -> 12.368976 | I13: =IF('Data Sheet'!I93>0,I12/'Data Sheet'!I93,0) -> 15.442276 | ... K13: =IF('Data Sheet'!K93>0,K12/'Data Sheet'!K93,0) -> 27.765984 | L13: =IF('Data Sheet'!$B6>0,'Profit & Loss'!L12/'Data Sheet'!$B6,0) -> 27.961207 | M13: =IF('Data Sheet'!$B6>0,'Profit & Loss'!M12/'Data Sheet'!$B6,0) -> 18.781411 | N13: =IF('Data Sheet'!$B6>0,'Profit & Loss'!N12/'Data Sheet'!$B6,0) -> 17.024144
A14: Price to earning | B14: =IF(B15>0,B15/B13,"") -> 26.497902 | C14: =IF(C15>0,C15/C13,"") -> 31.019466 | D14: =IF(D15>0,D15/D13,"") -> 25.93273 | E14: =IF(E15>0,E15/E13,"") -> 27.12553 | F14: =IF(F15>0,F15/F13,"") -> 12.925649 | G14: =IF(G15>0,G15/G13,"") -> 19.155475 | H14: =IF(H15>0,H15/H13,"") -> 18.995914 | I14: =IF(I15>0,I15/I13,"") -> 23.2796 | ... K14: =IF(K15>0,K15/K13,"") -> 14.757266 | L14: =IF(L13>0,L15/L13,0) -> 12.168645 | M14: =M25 -> 18.677087 | N14: =N25 -> 12.168645
A15: Price | B15: ='Data Sheet'!B90 -> 205.13 | C15: ='Data Sheet'!C90 -> 262.75 | D15: ='Data Sheet'!D90 -> 239.5 | E15: ='Data Sheet'!E90 -> 278.64 | F15: ='Data Sheet'!F90 -> 160.95 | G15: ='Data Sheet'!G90 -> 204.82 | H15: ='Data Sheet'!H90 -> 234.96 | I15: ='Data Sheet'!I90 -> 359.49 | ... K15: ='Data Sheet'!K90 -> 409.75 | L15: ='Data Sheet'!B8 -> 340.25 | M15: =M13*M14 -> 350.78205 | N15: =N13*N14 -> 207.16076
A17: RATIOS:
A18: Dividend Payout | B18: =IF('Data Sheet'!B30>0, 'Data Sheet'!B31/'Data Sheet'!B30, 0) -> 0.73199814 | C18: =IF('Data Sheet'!C30>0, 'Data Sheet'!C31/'Data Sheet'!C30, 0) -> 0.56077104 | D18: =IF('Data Sheet'!D30>0, 'Data Sheet'!D31/'Data Sheet'!D30, 0) -> 0.5576345 | E18: =IF('Data Sheet'!E30>0, 'Data Sheet'!E31/'Data Sheet'!E30, 0) -> 0.55976138 | F18: =IF('Data Sheet'!F30>0, 'Data Sheet'!F31/'Data Sheet'!F30, 0) -> 0.81513083 | G18: =IF('Data Sheet'!G30>0, 'Data Sheet'!G31/'Data Sheet'!G30, 0) -> 1.0053772 | H18: =IF('Data Sheet'!H30>0, 'Data Sheet'!H31/'Data Sheet'!H30, 0) -> 0.92974586 | I18: =IF('Data Sheet'!I30>0, 'Data Sheet'!I31/'Data Sheet'!I30, 0) -> 1.0037381 | ... K18: =IF('Data Sheet'!K30>0, 'Data Sheet'!K31/'Data Sheet'!K30, 0) -> 0.51681933
A19: OPM | B19: =IF(B6>0,B6/B4,0) -> 0.370776 | C19: =IF(C6>0,C6/C4,0) -> 0.36171097 | D19: =IF(D6>0,D6/D4,0) -> 0.38022999 | E19: =IF(E6>0,E6/E4,0) -> 0.38348265 | F19: =IF(F6>0,F6/F4,0) -> 0.39166716 | G19: =IF(G6>0,G6/G4,0) -> 0.34644059 | H19: =IF(H6>0,H6/H4,0) -> 0.34006606 | I19: =IF(I6>0,I6/I4,0) -> 0.36244517 | ... L19: =IF(L6>0,L6/L4,0) -> 0.33598874
G22: TRENDS: | H22: 10 YEARS | I22: 7 YEARS | J22: 5 YEARS | K22: 3 YEARS | L22: RECENT | M22: BEST | N22: WORST
G23: Sales Growth | H23: =IF(B4=0,"",POWER($K4/B4,1/9)-1) -> 0.075290157 | I23: =IF(D4=0,"",POWER($K4/D4,1/7)-1) -> 0.081772082 | J23: =IF(F4=0,"",POWER($K4/F4,1/5)-1) -> 0.088083322 | K23: =IF(H4=0,"",POWER($K4/H4, 1/3)-1) -> 0.074927782 | L23: =IF(ISERROR(MAX(IF(J4=0,"",(K4-J4)/J4),IF(K4=0,"",(L4-K4)/K4))),"",MAX(IF(J4=0,"",(K4-J4)/J4),IF(K4=0,"",(L4-K4)/K4))) -> 0.10880596 | M23: =MAX(K23:L23) -> 0.10880596 | N23: =MIN(H23:L23) -> 0.074927782
G24: OPM | H24: =IF(SUM(B4:$K$4)=0,"",SUMPRODUCT(B19:$K$19,B4:$K$4)/SUM(B4:$K$4)) -> 0.36333562 | I24: =IF(SUM(E4:$K$4)=0,"",SUMPRODUCT(E19:$K$19,E4:$K$4)/SUM(E4:$K$4)) -> 0.36106877 | J24: =IF(SUM(G4:$K$4)=0,"",SUMPRODUCT(G19:$K$19,G4:$K$4)/SUM(G4:$K$4)) -> 0.35306244 | K24: =IF(SUM(I4:$K$4)=0, "", SUMPRODUCT(I19:$K$19,I4:$K$4)/SUM(I4:$K$4)) -> 0.35826538 | L24: =L19 -> 0.33598874 | M24: =MAX(K24:L24) -> 0.35826538 | N24: =MIN(H24:L24) -> 0.33598874
G25: Price to Earning | H25: =IF(ISERROR(AVERAGEIF(B14:$L14,">0")),"",AVERAGEIF(B14:$L14,">0")) -> 21.487365 | I25: =IF(ISERROR(AVERAGEIF(E14:$L14,">0")),"",AVERAGEIF(E14:$L14,">0")) -> 19.113865 | J25: =IF(ISERROR(AVERAGEIF(G14:$L14,">0")),"",AVERAGEIF(G14:$L14,">0")) -> 18.809956 | K25: =IF(ISERROR(AVERAGEIF(I14:$L14,">0")),"",AVERAGEIF(I14:$L14,">0")) -> 18.677087 | L25: =L14 -> 12.168645 | M25: =MAX(K25:L25) -> 18.677087 | N25: =MIN(H25:L25) -> 12.168645
A27: Sales Growth (Y-O-Y) | E27: =E4/D4-1 -> 0.11256063 | F27: =F4/E4-1 -> 0.021682439 | G27: =G4/F4-1 -> -0.0026372963 | H27: =H4/G4-1 -> 0.23117498 | I27: =I4/H4-1 -> 0.16942152 | J27: =J4/I4-1 -> -0.042119724 | K27: =K4/J4-1 -> 0.10880596
A29: Gross Profit | E29: ='Data Sheet'!E17-'Data Sheet'!E18-'Data Sheet'!E19-'Data Sheet'!E20-'Data Sheet'!E21 -> 27895.13 | F29: ='Data Sheet'!F17-'Data Sheet'!F18-'Data Sheet'!F19-'Data Sheet'!F20-'Data Sheet'!F21 -> 27946.83 | G29: ='Data Sheet'!G17-'Data Sheet'!G18-'Data Sheet'!G19-'Data Sheet'!G20-'Data Sheet'!G21 -> 25548.73 | H29: ='Data Sheet'!H17-'Data Sheet'!H18-'Data Sheet'!H19-'Data Sheet'!H20-'Data Sheet'!H21 -> 30110.03 | I29: ='Data Sheet'!I17-'Data Sheet'!I18-'Data Sheet'!I19-'Data Sheet'!I20-'Data Sheet'!I21 -> 37635.94 | J29: ='Data Sheet'!J17-'Data Sheet'!J18-'Data Sheet'!J19-'Data Sheet'!J20-'Data Sheet'!J21 -> 37078.94 | K29: ='Data Sheet'!K17-'Data Sheet'!K18-'Data Sheet'!K19-'Data Sheet'!K20-'Data Sheet'!K21 -> 38572.61
A30: GPM | E30: =E29/E4 -> 0.57706604 | F30: =F29/F4 -> 0.5658662 | G30: =G29/G4 -> 0.51867748 | H30: =H29/H4 -> 0.49650026 | I30: =I29/I4 -> 0.53068887 | J30: =J29/J4 -> 0.54582484 | K30: =K29/K4 -> 0.51209373
A31: EBITDA Margins | E31: =E6/E4 -> 0.38348265 | F31: =F6/F4 -> 0.39166716 | G31: =G6/G4 -> 0.34644059 | H31: =H6/H4 -> 0.34006606 | I31: =I6/I4 -> 0.36244517 | J31: =J6/J4 -> 0.37077596 | K31: =K6/K4 -> 0.34304706
A32: EBIT Margins | E32: =(E6-E8)/E4 -> 0.354591 | F32: =(F6-F8)/F4 -> 0.35836109 | G32: =(G6-G8)/G4 -> 0.31303265 | H32: =(H6-H8)/H4 -> 0.31149944 | I32: =(I6-I8)/I4 -> 0.33693707 | J32: =(J6-J8)/J4 -> 0.34842932 | K32: =(K6-K8)/K4 -> 0.32119035
A33: Net Margins (%) | E33: =E12/E4 -> 0.2604973 | F33: =F12/F4 -> 0.30991988 | G33: =G12/G4 -> 0.26719187 | H33: =H12/H4 -> 0.25134431 | I33: =I12/I4 -> 0.27061368 | J33: =J12/J4 -> 0.30116584 | K33: =K12/K4 -> 0.46129964
A36: EPS Growth (Y-O-Y) | E36: =E13/D13-1 -> 0.11226415 | F36: =F13/E13-1 -> 0.21219753 | G36: =G13/F13-1 -> -0.14130126 | H36: =H13/G13-1 -> 0.15678939 | I36: =I13/H13-1 -> 0.2484684 | J36: =J13/I13-1 -> 0.0611831 | K36: =K13/J13-1 -> 0.69438246
A38: Divident payout | D38: =D13*D18 -> 5.1499963 | E38: =E13*E18 -> 5.7500041 | F38: =F13*F18 -> 10.149998 | G38: =G13*G18 -> 10.75 | H38: =H13*H18 -> 11.500004 | I38: =I13*I18 -> 15.5 | J38: =J13*J18 -> 13.749998 | K38: =K13*K18 -> 14.349997
A39: Divident growth | E39: =E38/D38-1 -> 0.11650645 | F39: =F38/E38-1 -> 0.76521571 | G39: =G38/F38-1 -> 0.059113555 | H39: =H38/G38-1 -> 0.069767819 | I39: =I38/H38-1 -> 0.34782561 | J39: =J38/I38-1 -> -0.11290335 | K39: =K38/J38-1 -> 0.043636312
A41: Market Cap | E41: ='Data Sheet'!E93*'Data Sheet'!E90 -> 341573.63 | F41: ='Data Sheet'!F93*'Data Sheet'!F90 -> 197842.96 | G41: ='Data Sheet'!G93*'Data Sheet'!G90 -> 252108.84 | H41: ='Data Sheet'!H93*'Data Sheet'!H90 -> 289548.26 | I41: ='Data Sheet'!I93*'Data Sheet'!I90 -> 446774.17 | J41: ='Data Sheet'!J93*'Data Sheet'!J90 -> 501298.16 | K41: ='Data Sheet'!K93*'Data Sheet'!K90 -> 512765.25
A42: Debt | E42: ='Data Sheet'!E59 -> 13.44 | F42: ='Data Sheet'!F59 -> 277.45 | G42: ='Data Sheet'!G59 -> 270.83 | H42: ='Data Sheet'!H59 -> 249.44 | I42: ='Data Sheet'!I59 -> 306.04 | J42: ='Data Sheet'!J59 -> 303.43 | K42: ='Data Sheet'!K59 -> 284.54
A43: cash | E43: ='Data Sheet'!E69 -> 4152.03 | F43: ='Data Sheet'!F69 -> 7277.34 | G43: ='Data Sheet'!G69 -> 4659.02 | H43: ='Data Sheet'!H69 -> 4654.42 | I43: ='Data Sheet'!I69 -> 4880.19 | J43: ='Data Sheet'!J69 -> 7217.68 | K43: ='Data Sheet'!K69 -> 4012.36
A46: Enterprise value | E46: =E41+E42-E43 -> 337435.04 | F46: =F41+F42-F43 -> 190843.07 | G46: =G41+G42-G43 -> 247720.65 | H46: =H41+H42-H43 -> 285143.28 | I46: =I41+I42-I43 -> 442200.02 | J46: =J41+J42-J43 -> 494383.91 | K46: =K41+K42-K43 -> 509037.43
A48: ev% | E48: =E46/E6 -> 18.202942 | F48: =F46/F6 -> 9.8659847 | G48: =G46/G6 -> 14.516487 | H48: =H46/H6 -> 13.826369 | I48: =I46/I6 -> 17.203375 | J48: =J46/J6 -> 19.628122 | K48: =K46/K6 -> 19.70001
A49: ev sales | E49: =E46/E4 -> 6.9805125 | F49: =F46/F4 -> 3.8641822 | G49: =G46/G4 -> 5.0291002 | H49: =H46/H4 -> 4.7018788 | I49: =I46/I4 -> 6.2352802 | J49: =J46/J4 -> 7.2776357 | K49: =K46/K4 -> 6.7580305
A51: P/B | E51: =E46/'Balance Sheet'!E26 -> 5.7056151 | F51: =F46/'Balance Sheet'!F26 -> 2.9237557 | G51: =G46/'Balance Sheet'!G26 -> 4.1049142 | H51: =H46/'Balance Sheet'!H26 -> 4.565538 | I51: =I46/'Balance Sheet'!I26 -> 6.3943079 | J51: =J46/'Balance Sheet'!J26 -> 6.6354022

Sheet Quarters
A1: ='Profit & Loss'!A1 -> ITC LTD | E1: =UPDATE | J1: SCREENER.IN
A3: Narration | B3: ='Data Sheet'!B41 -> 45107 | C3: ='Data Sheet'!C41 -> 45199 | D3: ='Data Sheet'!D41 -> 45291 | E3: ='Data Sheet'!E41 -> 45382 | F3: ='Data Sheet'!F41 -> 45473 | G3: ='Data Sheet'!G41 -> 45565 | H3: ='Data Sheet'!H41 -> 45657 | I3: ='Data Sheet'!I41 -> 45747 | ... K3: ='Data Sheet'!K41 -> 45930
A4: Sales | B4: ='Data Sheet'!B42 -> 17164.46 | C4: ='Data Sheet'!C42 -> 17774.47 | D4: ='Data Sheet'!D42 -> 17195.24 | E4: ='Data Sheet'!E42 -> 17037.8 | F4: ='Data Sheet'!F42 -> 17777.81 | G4: ='Data Sheet'!G42 -> 19990.36 | H4: ='Data Sheet'!H42 -> 18790.17 | I4: ='Data Sheet'!I42 -> 18765 | ... K4: ='Data Sheet'!K42 -> 19501.63
A5: Expenses | B5: ='Data Sheet'!B43 -> 10494.39 | C5: ='Data Sheet'!C43 -> 11320.23 | D5: ='Data Sheet'!D43 -> 10985.01 | E5: ='Data Sheet'!E43 -> 10735.73 | F5: ='Data Sheet'!F43 -> 11232.97 | G5: ='Data Sheet'!G43 -> 13438.28 | H5: ='Data Sheet'!H43 -> 12428.27 | I5: ='Data Sheet'!I43 -> 12245.61 | ... K5: ='Data Sheet'!K43 -> 12806.94
A6: Operating Profit | B6: ='Data Sheet'!B50 -> 6670.07 | C6: ='Data Sheet'!C50 -> 6454.24 | D6: ='Data Sheet'!D50 -> 6210.23 | E6: ='Data Sheet'!E50 -> 6302.07 | F6: ='Data Sheet'!F50 -> 6544.84 | G6: ='Data Sheet'!G50 -> 6552.08 | H6: ='Data Sheet'!H50 -> 6361.9 | I6: ='Data Sheet'!I50 -> 6519.39 | ... K6: ='Data Sheet'!K50 -> 6694.69
A7: Other Income | B7: ='Data Sheet'!B44 -> 722.3 | C7: ='Data Sheet'!C44 -> 673.5 | D7: ='Data Sheet'!D44 -> 820.26 | E7: ='Data Sheet'!E44 -> 868 | F7: ='Data Sheet'!F44 -> 771.13 | G7: ='Data Sheet'!G44 -> 690.31 | H7: ='Data Sheet'!H44 -> 803.4 | I7: ='Data Sheet'!I44 -> 15391.28 | ... K7: ='Data Sheet'!K44 -> 738.84
A8: Depreciation | B8: ='Data Sheet'!B45 -> 442.46 | C8: ='Data Sheet'!C45 -> 453.04 | D8: ='Data Sheet'!D45 -> 384.04 | E8: ='Data Sheet'!E45 -> 385.09 | F8: ='Data Sheet'!F45 -> 403.13 | G8: ='Data Sheet'!G45 -> 416.18 | H8: ='Data Sheet'!H45 -> 415.98 | I8: ='Data Sheet'!I45 -> 411.03 | ... K8: ='Data Sheet'!K45 -> 434.8
A9: Interest | B9: ='Data Sheet'!B46 -> 9.9 | C9: ='Data Sheet'!C46 -> 9.87 | D9: ='Data Sheet'!D46 -> 11.94 | E9: ='Data Sheet'!E46 -> 10.72 | F9: ='Data Sheet'!F46 -> 9.6 | G9: ='Data Sheet'!G46 -> 14.73 | H9: ='Data Sheet'!H46 -> 9.82 | I9: ='Data Sheet'!I46 -> 10.91 | ... K9: ='Data Sheet'!K46 -> 20.05
A10: Profit before tax | B10: ='Data Sheet'!B47 -> 6940.01 | C10: ='Data Sheet'!C47 -> 6664.83 | D10: ='Data Sheet'!D47 -> 6634.51 | E10: ='Data Sheet'!E47 -> 6774.26 | F10: ='Data Sheet'!F47 -> 6903.24 | G10: ='Data Sheet'!G47 -> 6811.48 | H10: ='Data Sheet'!H47 -> 6739.5 | I10: ='Data Sheet'!I47 -> 21488.73 | ... K10: ='Data Sheet'!K47 -> 6978.68
A11: Tax | B11: ='Data Sheet'!B48 -> 1759.89 | C11: ='Data Sheet'!C48 -> 1700.31 | D11: ='Data Sheet'!D48 -> 1227.99 | E11: ='Data Sheet'!E48 -> 1583.55 | F11: ='Data Sheet'!F48 -> 1726.25 | G11: ='Data Sheet'!G48 -> 1757.05 | H11: ='Data Sheet'!H48 -> 1726.32 | I11: ='Data Sheet'!I48 -> 1680.85 | ... K11: ='Data Sheet'!K48 -> 1792.13
A12: Net profit | B12: ='Data Sheet'!B49 -> 5104.93 | C12: ='Data Sheet'!C49 -> 4898.07 | D12: ='Data Sheet'!D49 -> 5335.23 | E12: ='Data Sheet'!E49 -> 5120.55 | F12: ='Data Sheet'!F49 -> 5091.59 | G12: ='Data Sheet'!G49 -> 4992.87 | H12: ='Data Sheet'!H49 -> 4934.8 | I12: ='Data Sheet'!I49 -> 19727.37 | ... K12: ='Data Sheet'!K49 -> 5126.11
A14: OPM | B14: =IF(B4>0,B6/B4,"") -> 0.38859772 | C14: =IF(C4>0,C6/C4,"") -> 0.36311856 | D14: =IF(D4>0,D6/D4,"") -> 0.36115983 | E14: =IF(E4>0,E6/E4,"") -> 0.36988754 | F14: =IF(F4>0,F6/F4,"") -> 0.36814658 | G14: =IF(G4>0,G6/G4,"") -> 0.32776198 | H14: =IF(H4>0,H6/H4,"") -> 0.33857597 | I14: =IF(I4>0,I6/I4,"") -> 0.34742286 | ... K14: =IF(K4>0,K6/K4,"") -> 0.34328874

Sheet Sheet3
B1: Date | D1: Vol. | N1: date | O1: Vol
B2: 43357 | C2: 307.14662 | D2: 12.82 | N2: 43357 | O2: 12.82M
B3: 43360 | C3: 302.05074 | D3: 5.83 | N3: 43360 | O3: 5.83M
B4: 43361 | C4: 303.23757 | D4: 8.2 | N4: 43361 | O4: 8.20M
B5: 43362 | C5: 299.68566 | D5: 6.15 | N5: 43362 | O5: 6.15M
B6: 43364 | C6: 303.90624 | D6: 16.34 | N6: 43364 | O6: 16.34M
B7: 43367 | C7: 298.00871 | D7: 14.45 | N7: 43367 | O7: 14.45M
B8: 43368 | C8: 301.11778 | D8: 13.27 | N8: 43368 | O8: 13.27M
B9: 43369 | C9: 293.228 | D9: 19.89 | N9: 43369 | O9: 19.89M
B10: 43370 | C10: 293.29853 | D10: 12.08 | N10: 43370 | O10: 12.08M
B11: 43371 | C11: 297.70475 | D11: 24.61 | N11: 43371 | O11: 24.61M
B12: 43374 | C12: 297.10654 | D12: 9.03 | N12: 43374 | O12: 9.03M
B13: 43376 | C13: 295.21889 | D13: 7.57 | N13: 43376 | O13: 7.57M
... B27: 43397 | C27: 287.73245 | D27: 8.69 | N27: 43397 | O27: 8.69M
B28: 43398 | C28: 287.55201 | D28: 9.58 | G28: Shareholder's name | H28: Total Shares Held | I28: Shareholding (%) | J28: Quarter Ending | N28: 43398 | O28: 9.58M
B29: 43399 | C29: 280.9649 | D29: 21.48 | G29: Tobacco Manufacturers (India) Limited | H29: 2228495863 | I29: 17.79 | J29: 45901 | N29: 43399 | O29: 21.48M
B30: 43402 | C30: 283.47364 | D30: 11.34 | G30: Life Insurance Corporation of India | H30: 1985807233 | I30: 15.86 | J30: 45901 | N30: 43402 | O30: 11.34M
B31: 43403 | C31: 278.99464 | D31: 6.85 | G31: Specified Undertaking of the Unit Trust of India | H31: 974531427 | I31: 7.78 | J31: 45901 | N31: 43403 | O31: 6.85M
B32: 43404 | C32: 280.08852 | D32: 13.5 | G32: Myddleton Investment Company Limited | H32: 486311940 | I32: 3.88 | J32: 45901 | N32: 43404 | O32: 13.50M
B33: 43405 | C33: 277.42663 | D33: 9.45 | G33: SBI Mutual Funds | H33: 407984095 | I33: 3.26 | J33: 45901 | N33: 43405 | O33: 9.45M
B34: 43406 | C34: 283.19025 | D34: 11.64 | G34: QIB - Insurance Company Registered | H34: 339904658 | I34: 2.71 | J34: 45901 | N34: 43406 | O34: 11.64M
B35: 43409 | C35: 279.63607 | D35: 7.38 | G35: ICICI Prudential Mutual Funds | H35: 285350493 | I35: 2.28 | J35: 45901 | N35: 43409 | O35: 7.38M
B36: 43410 | C36: 277.32274 | D36: 9.77 | G36: GQG Partners Emerging Markets Equity Fund | H36: 263434398 | I36: 2.1 | J36: 45901 | N36: 43410 | O36: 9.77M
B37: 43411 | C37: 280.02228 | D37: 957.14K | G37: General Insurance Corporation of India | H37: 217085508 | I37: 1.73 | J37: 45901 | N37: 43411 | O37: 957.14K
B38: 43413 | C38: 277.27773 | D38: 15.03 | G38: Goldman Sachs Trust II - Goldman Sachs GQG Partners International Opportunities Fund | H38: 207091795 | I38: 1.65 | J38: 45901 | N38: 43413 | O38: 15.03M
B39: 43416 | C39: 273.88369 | D39: 7.05 | N39: 43416 | O39: 7.05M
B40: 43417 | C40: 276.81955 | D40: 6.7 | N40: 43417 | O40: 6.70M
B41: 43418 | C41: 276.45387 | D41: 6.92 | N41: 43418 | O41: 6.92M
B42: 43419 | C42: 274.51949 | D42: 12.15 | N42: 43419 | O42: 12.15M
B43: 43420 | C43: 276.52926 | D43: 12.64 | N43: 43420 | O43: 12.64M
B44: 43423 | C44: 284.41837 | D44: 16.72 | N44: 43423 | O44: 16.72M
B45: 43424 | C45: 283.85653 | D45: 7.8 | N45: 43424 | O45: 7.80M
B46: 43425 | C46: 281.77085 | D46: 5.65 | N46: 43425 | O46: 5.65M
B47: 43426 | C47: 280.51234 | D47: 6.68 | N47: 43426 | O47: 6.68M
B48: 43430 | C48: 285.59745 | D48: 8.95 | N48: 43430 | O48: 8.95M
B49: 43431 | C49: 284.85798 | D49: 6.88 | N49: 43431 | O49: 6.88M
B50: 43432 | C50: 282.22625 | D50: 8.86 | N50: 43432 | O50: 8.86M
... B60: 43446 | C60: 276.03647 | D60: 10.08 | N60: 43446 | O60: 10.08M
B61: 43447 | C61: 275.30743 | D61: 15.82 | K61: 10000000 | N61: 43447 | O61: 15.82M
B62: 43448 | C62: 275.74559 | D62: 8.59 | N62: 43448 | O62: 8.59M
...

Sheet Balance Sheet
A1: ='Profit & Loss'!A1 -> ITC LTD | E1: =UPDATE | J1: SCREENER.IN
A3: Narration | B3: ='Data Sheet'!B56 -> 42460 | C3: ='Data Sheet'!C56 -> 42825 | D3: ='Data Sheet'!D56 -> 43190 | E3: ='Data Sheet'!E56 -> 43555 | F3: ='Data Sheet'!F56 -> 43921 | G3: ='Data Sheet'!G56 -> 44286 | H3: ='Data Sheet'!H56 -> 44651 | I3: ='Data Sheet'!I56 -> 45016 | ... K3: ='Data Sheet'!K56 -> 45747
A4: Equity Share Capital | B4: ='Data Sheet'!B57 -> 804.72 | C4: ='Data Sheet'!C57 -> 1214.74 | D4: ='Data Sheet'!D57 -> 1220.43 | E4: ='Data Sheet'!E57 -> 1225.86 | F4: ='Data Sheet'!F57 -> 1229.22 | G4: ='Data Sheet'!G57 -> 1230.88 | H4: ='Data Sheet'!H57 -> 1232.33 | I4: ='Data Sheet'!I57 -> 1242.8 | ... K4: ='Data Sheet'!K57 -> 1251.41
A5: Reserves | B5: ='Data Sheet'!B58 -> 41874.8 | C5: ='Data Sheet'!C58 -> 45198.19 | D5: ='Data Sheet'!D58 -> 51289.68 | E5: ='Data Sheet'!E58 -> 57915.01 | F5: ='Data Sheet'!F58 -> 64044.04 | G5: ='Data Sheet'!G58 -> 59116.46 | H5: ='Data Sheet'!H58 -> 61223.24 | I5: ='Data Sheet'!I58 -> 67912.46 | ... K5: ='Data Sheet'!K58 -> 68778.64
A6: Borrowings | B6: ='Data Sheet'!B59 -> 83.78 | C6: ='Data Sheet'!C59 -> 45.72 | D6: ='Data Sheet'!D59 -> 35.92 | E6: ='Data Sheet'!E59 -> 13.44 | F6: ='Data Sheet'!F59 -> 277.45 | G6: ='Data Sheet'!G59 -> 270.83 | H6: ='Data Sheet'!H59 -> 249.44 | I6: ='Data Sheet'!I59 -> 306.04 | ... K6: ='Data Sheet'!K59 -> 284.54
A7: Other Liabilities | B7: ='Data Sheet'!B60 -> 8888.04 | C7: ='Data Sheet'!C60 -> 9439.67 | D7: ='Data Sheet'!D60 -> 11694.85 | E7: ='Data Sheet'!E60 -> 12584.73 | F7: ='Data Sheet'!F60 -> 11760.04 | G7: ='Data Sheet'!G60 -> 13142.59 | H7: ='Data Sheet'!H60 -> 14491.01 | I7: ='Data Sheet'!I60 -> 16369.66 | ... K7: ='Data Sheet'!K60 -> 17688.11
A8: Total | B8: ='Data Sheet'!B61 -> 51651.34 | C8: ='Data Sheet'!C61 -> 55898.32 | D8: ='Data Sheet'!D61 -> 64240.88 | E8: ='Data Sheet'!E61 -> 71739.04 | F8: ='Data Sheet'!F61 -> 77310.75 | G8: ='Data Sheet'!G61 -> 73760.76 | H8: ='Data Sheet'!H61 -> 77196.02 | I8: ='Data Sheet'!I61 -> 85830.96 | ... K8: ='Data Sheet'!K61 -> 88002.7
A10: Net Block | B10: ='Data Sheet'!B62 -> 15106.63 | C10: ='Data Sheet'!C62 -> 15893.48 | D10: ='Data Sheet'!D62 -> 16523.96 | E10: ='Data Sheet'!E62 -> 19374.19 | F10: ='Data Sheet'!F62 -> 21713.34 | G10: ='Data Sheet'!G62 -> 23298.48 | H10: ='Data Sheet'!H62 -> 24231.59 | I10: ='Data Sheet'!I62 -> 25851.27 | ... K10: ='Data Sheet'!K62 -> 21954.85
A11: Capital Work in Progress | B11: ='Data Sheet'!B63 -> 2559.72 | C11: ='Data Sheet'!C63 -> 3729.89 | D11: ='Data Sheet'!D63 -> 5508.33 | E11: ='Data Sheet'!E63 -> 4136.42 | F11: ='Data Sheet'!F63 -> 3256.46 | G11: ='Data Sheet'!G63 -> 4011.29 | H11: ='Data Sheet'!H63 -> 3225.54 | I11: ='Data Sheet'!I63 -> 3003.3 | ... K11: ='Data Sheet'!K63 -> 1090.91
A12: Investments | B12: ='Data Sheet'!B64 -> 11747.59 | C12: ='Data Sheet'!C64 -> 17581.38 | D12: ='Data Sheet'!D64 -> 22052.86 | E12: ='Data Sheet'!E64 -> 25043.49 | F12: ='Data Sheet'!F64 -> 28663.35 | G12: ='Data Sheet'!G64 -> 24870.87 | H12: ='Data Sheet'!H64 -> 24841.01 | I12: ='Data Sheet'!I64 -> 29415.02 | ... K12: ='Data Sheet'!K64 -> 34719.82
A13: Other Assets | B13: ='Data Sheet'!B65 -> 22237.4 | C13: ='Data Sheet'!C65 -> 18693.57 | D13: ='Data Sheet'!D65 -> 20155.73 | E13: ='Data Sheet'!E65 -> 23184.94 | F13: ='Data Sheet'!F65 -> 23677.6 | G13: ='Data Sheet'!G65 -> 21580.12 | H13: ='Data Sheet'!H65 -> 24897.88 | I13: ='Data Sheet'!I65 -> 27561.37 | ... K13: ='Data Sheet'!K65 -> 30237.12
A14: Total | B14: ='Data Sheet'!B66 -> 51651.34 | C14: ='Data Sheet'!C66 -> 55898.32 | D14: ='Data Sheet'!D66 -> 64240.88 | E14: ='Data Sheet'!E66 -> 71739.04 | F14: ='Data Sheet'!F66 -> 77310.75 | G14: ='Data Sheet'!G66 -> 73760.76 | H14: ='Data Sheet'!H66 -> 77196.02 | I14: ='Data Sheet'!I66 -> 85830.96 | ... K14: ='Data Sheet'!K66 -> 88002.7
A16: Working Capital | B16: =B13-B7 -> 13349.36 | C16: =C13-C7 -> 9253.9 | D16: =D13-D7 -> 8460.88 | E16: =E13-E7 -> 10600.21 | F16: =F13-F7 -> 11917.56 | G16: =G13-G7 -> 8437.53 | H16: =H13-H7 -> 10406.87 | I16: =I13-I7 -> 11191.71 | ... K16: =K13-K7 -> 12549.01
A17: Debtors | B17: ='Data Sheet'!B67 -> 1917.18 | C17: ='Data Sheet'!C67 -> 2474.29 | D17: ='Data Sheet'!D67 -> 2682.29 | E17: ='Data Sheet'!E67 -> 4035.28 | F17: ='Data Sheet'!F67 -> 2562.48 | G17: ='Data Sheet'!G67 -> 2501.7 | H17: ='Data Sheet'!H67 -> 2461.9 | I17: ='Data Sheet'!I67 -> 2956.17 | ... K17: ='Data Sheet'!K67 -> 4719.67
A18: Inventory | B18: ='Data Sheet'!B68 -> 9062.1 | C18: ='Data Sheet'!C68 -> 8116.1 | D18: ='Data Sheet'!D68 -> 7495.09 | E18: ='Data Sheet'!E68 -> 7859.56 | F18: ='Data Sheet'!F68 -> 8879.33 | G18: ='Data Sheet'!G68 -> 10397.16 | H18: ='Data Sheet'!H68 -> 10864.15 | I18: ='Data Sheet'!I68 -> 11771.16 | ... K18: ='Data Sheet'!K68 -> 15637.56
A20: Debtor Days | B20: =IF('Profit & Loss'!B4>0,'Balance Sheet'!B17/('Profit & Loss'!B4/365),0) -> 17.854892 | C20: =IF('Profit & Loss'!C4>0,'Balance Sheet'!C17/('Profit & Loss'!C4/365),0) -> 21.116823 | D20: =IF('Profit & Loss'!D4>0,'Balance Sheet'!D17/('Profit & Loss'!D4/365),0) -> 22.53302 | E20: =IF('Profit & Loss'!E4>0,'Balance Sheet'!E17/('Profit & Loss'!E4/365),0) -> 30.469383 | F20: =IF('Profit & Loss'!F4>0,'Balance Sheet'!F17/('Profit & Loss'!F4/365),0) -> 18.938019 | G20: =IF('Profit & Loss'!G4>0,'Balance Sheet'!G17/('Profit & Loss'!G4/365),0) -> 18.537714 | H20: =IF('Profit & Loss'!H4>0,'Balance Sheet'!H17/('Profit & Loss'!H4/365),0) -> 14.817385 | I20: =IF('Profit & Loss'!I4>0,'Balance Sheet'!I17/('Profit & Loss'!I4/365),0) -> 15.214563 | ... K20: =IF('Profit & Loss'!K4>0,'Balance Sheet'!K17/('Profit & Loss'!K4/365),0) -> 22.870462
A21: Inventory Turnover | B21: =IF('Balance Sheet'!B18>0,'Profit & Loss'!B4/'Balance Sheet'!B18,0) -> 4.3248364 | C21: =IF('Balance Sheet'!C18>0,'Profit & Loss'!C4/'Balance Sheet'!C18,0) -> 5.2694767 | D21: =IF('Balance Sheet'!D18>0,'Profit & Loss'!D4/'Balance Sheet'!D18,0) -> 5.7969871 | E21: =IF('Balance Sheet'!E18>0,'Profit & Loss'!E4/'Balance Sheet'!E18,0) -> 6.1504181 | F21: =IF('Balance Sheet'!F18>0,'Profit & Loss'!F4/'Balance Sheet'!F18,0) -> 5.5620976 | G21: =IF('Balance Sheet'!G18>0,'Profit & Loss'!G4/'Balance Sheet'!G18,0) -> 4.737587 | H21: =IF('Balance Sheet'!H18>0,'Profit & Loss'!H4/'Balance Sheet'!H18,0) -> 5.5820787 | I21: =IF('Balance Sheet'!I18>0,'Profit & Loss'!I4/'Balance Sheet'!I18,0) -> 6.0248123 | ... K21: =IF('Balance Sheet'!K18>0,'Profit & Loss'!K4/'Balance Sheet'!K18,0) -> 4.8168218
A23: Return on Equity | B23: =IF(SUM('Balance Sheet'!B4:B5)>0,'Profit & Loss'!B12/SUM('Balance Sheet'!B4:B5),"") -> 0.21894459 | C23: =IF(SUM('Balance Sheet'!C4:C5)>0,'Profit & Loss'!C12/SUM('Balance Sheet'!C4:C5),"") -> 0.22169339 | D23: =IF(SUM('Balance Sheet'!D4:D5)>0,'Profit & Loss'!D12/SUM('Balance Sheet'!D4:D5),"") -> 0.21464819 | E23: =IF(SUM('Balance Sheet'!E4:E5)>0,'Profit & Loss'!E12/SUM('Balance Sheet'!E4:E5),"") -> 0.21292095 | F23: =IF(SUM('Balance Sheet'!F4:F5)>0,'Profit & Loss'!F12/SUM('Balance Sheet'!F4:F5),"") -> 0.23449465 | G23: =IF(SUM('Balance Sheet'!G4:G5)>0,'Profit & Loss'!G12/SUM('Balance Sheet'!G4:G5),"") -> 0.21809064 | H23: =IF(SUM('Balance Sheet'!H4:H5)>0,'Profit & Loss'!H12/SUM('Balance Sheet'!H4:H5),"") -> 0.24405605 | I23: =IF(SUM('Balance Sheet'!I4:I5)>0,'Profit & Loss'!I12/SUM('Balance Sheet'!I4:I5),"") -> 0.27751555 | ... K23: =IF(SUM('Balance Sheet'!K4:K5)>0,'Profit & Loss'!K12/SUM('Balance Sheet'!K4:K5),"") -> 0.49616743
A24: Return on Capital Emp | C24: =IF((B4+B5+B6+C4+C5+C6)>0,('Profit & Loss'!C10+'Profit & Loss'!C9)*2/(B4+B5+B6+C4+C5+C6),"") -> 0.36034518 | D24: =IF((C4+C5+C6+D4+D5+D6)>0,('Profit & Loss'!D10+'Profit & Loss'!D9)*2/(C4+C5+C6+D4+D5+D6),"") -> 0.35400589 | E24: =IF((D4+D5+D6+E4+E5+E6)>0,('Profit & Loss'!E10+'Profit & Loss'!E9)*2/(D4+D5+D6+E4+E5+E6),"") -> 0.34415688 | F24: =IF((E4+E5+E6+F4+F5+F6)>0,('Profit & Loss'!F10+'Profit & Loss'!F9)*2/(E4+E5+E6+F4+F5+F6),"") -> 0.32261652 | G24: =IF((F4+F5+F6+G4+G5+G6)>0,('Profit & Loss'!G10+'Profit & Loss'!G9)*2/(F4+F5+F6+G4+G5+G6),"") -> 0.28527066 | H24: =IF((G4+G5+G6+H4+H5+H6)>0,('Profit & Loss'!H10+'Profit & Loss'!H9)*2/(G4+G5+G6+H4+H5+H6),"") -> 0.33733253 | I24: =IF((H4+H5+H6+I4+I5+I6)>0,('Profit & Loss'!I10+'Profit & Loss'!I9)*2/(H4+H5+H6+I4+I5+I6),"") -> 0.39333609 | J24: =IF((I4+I5+I6+J4+J5+J6)>0,('Profit & Loss'!J10+'Profit & Loss'!J9)*2/(I4+I5+I6+J4+J5+J6),"") -> 0.37429273 | K24: =IF((J4+J5+J6+K4+K5+K6)>0,('Profit & Loss'!K10+'Profit & Loss'!K9)*2/(J4+J5+J6+K4+K5+K6),"") -> 0.57864605
A26: Book Value | E26: =E4+E5 -> 59140.87 | F26: =F4+F5 -> 65273.26 | G26: =G4+G5 -> 60347.34 | H26: =H4+H5 -> 62455.57 | I26: =I4+I5 -> 69155.26 | J26: =J4+J5 -> 74507

Sheet Cash Flow
A1: ='Balance Sheet'!A1 -> ITC LTD | E1: =UPDATE | J1: SCREENER.IN
A3: Narration | B3: ='Data Sheet'!B81 -> 42460 | C3: ='Data Sheet'!C81 -> 42825 | D3: ='Data Sheet'!D81 -> 43190 | E3: ='Data Sheet'!E81 -> 43555 | F3: ='Data Sheet'!F81 -> 43921 | G3: ='Data Sheet'!G81 -> 44286 | H3: ='Data Sheet'!H81 -> 44651 | I3: ='Data Sheet'!I81 -> 45016 | ... K3: ='Data Sheet'!K81 -> 45747
A4: Cash from Operating Activity | B4: ='Data Sheet'!B82 -> 9799.04 | C4: ='Data Sheet'!C82 -> 10627.31 | D4: ='Data Sheet'!D82 -> 13169.4 | E4: ='Data Sheet'!E82 -> 12583.41 | F4: ='Data Sheet'!F82 -> 14689.66 | G4: ='Data Sheet'!G82 -> 12526.97 | H4: ='Data Sheet'!H82 -> 15775.51 | I4: ='Data Sheet'!I82 -> 18877.55 | ... K4: ='Data Sheet'!K82 -> 17627.04
A5: Cash from Investing Activity | B5: ='Data Sheet'!B83 -> -3920.73 | C5: ='Data Sheet'!C83 -> -3250.93 | D5: ='Data Sheet'!D83 -> -7113.89 | E5: ='Data Sheet'!E83 -> -5545.68 | F5: ='Data Sheet'!F83 -> -6174.02 | G5: ='Data Sheet'!G83 -> 5739.98 | H5: ='Data Sheet'!H83 -> -2238.49 | I5: ='Data Sheet'!I83 -> -5732.29 | ... K5: ='Data Sheet'!K83 -> -563.84
A6: Cash from Financing Activity | B6: ='Data Sheet'!B84 -> -5612.52 | C6: ='Data Sheet'!C84 -> -7301.03 | D6: ='Data Sheet'!D84 -> -6221.13 | E6: ='Data Sheet'!E84 -> -6868.64 | F6: ='Data Sheet'!F84 -> -8181.48 | G6: ='Data Sheet'!G84 -> -18633.83 | H6: ='Data Sheet'!H84 -> -13580.5 | I6: ='Data Sheet'!I84 -> -13006.03 | ... K6: ='Data Sheet'!K84 -> -17037.4
A7: Net Cash Flow | B7: ='Data Sheet'!B85 -> 265.79 | C7: ='Data Sheet'!C85 -> 75.35 | D7: ='Data Sheet'!D85 -> -165.62 | E7: ='Data Sheet'!E85 -> 169.09 | F7: ='Data Sheet'!F85 -> 334.16 | G7: ='Data Sheet'!G85 -> -366.88 | H7: ='Data Sheet'!H85 -> -43.48 | I7: ='Data Sheet'!I85 -> 139.23 | ... K7: ='Data Sheet'!K85 -> 25.8

Sheet Customization
A1: How to use it?
A3: You can customize this workbook as you want.
B4: You can add custom formating, add conditional formating, add your own formulas… do ANYTHING.
B5: Please don't edit the "Data Sheet" only.
A7: After customization, you can upload this back on Screener.
B8: Upload on: | C8: https://www.screener.in/excel/
A10: Download your customized workbooks now onwards.
B11: Now whenever you will "Export to excel" from Screener, it will export your customized file.
A14: TESTING:
B15: This is a testing feature currently.
B16: You can report any formula errors on the worksheet at: support@screener.in

Sheet Data Sheet
A1: COMPANY NAME | B1: ITC LTD | E1: =IF(B2<>B3, "A NEW VERSION OF THE WORKSHEET IS AVAILABLE", "")
A2: LATEST VERSION | B2: 2.1 | E2: PLEASE DO NOT MAKE ANY CHANGES TO THIS SHEET
A3: CURRENT VERSION | B3: 2.1
A5: META
A6: Number of shares | B6: =IF(B9>0, B9/B8, 0) -> 1252.8958
A7: Face Value | B7: 1
A8: Current Price | B8: 340.25
A9: Market Capitalization | B9: 426297.81
A15: PROFIT & LOSS
A16: Report Date | B16: 42460 | C16: 42825 | D16: 43190 | E16: 43555 | F16: 43921 | G16: 44286 | H16: 44651 | I16: 45016 | J16: 45382 | K16: 45747
A17: Sales | B17: 39192.1 | C17: 42767.6 | D17: 43448.94 | E17: 48339.58 | F17: 49387.7 | G17: 49257.45 | H17: 60644.54 | I17: 70919.03 | J17: 67931.94 | K17: 75323.34
A18: Raw Material Cost | B18: 13763.88 | C18: 15456.59 | D18: 14827.72 | E18: 17623.52 | F18: 18048.6 | G18: 20776.71 | H18: 27071.07 | I18: 29364.36 | J18: 27348.57 | K18: 32704.37
A19: Change in Inventory | B19: 195.38 | C19: -592.57 | D19: -1027.76 | E19: 203.19 | F19: 703.13 | G19: 645.27 | H19: 686 | I19: 358.59 | J19: 367.77 | K19: 725.65
A20: Power and Fuel | B20: 571.88 | C20: 584.33 | D20: 653.5 | E20: 746.73 | F20: 780.85 | G20: 699.56 | H20: 889.77 | I20: 1232.34 | J20: 952.9 | K20: 975.35
A21: Other Mfr. Exp | B21: 1581.59 | C21: 1683.9 | D21: 1697.62 | E21: 1871.01 | F21: 1908.29 | G21: 1587.18 | H21: 1887.67 | I21: 2327.8 | J21: 2183.76 | K21: 2345.36
A22: Employee Cost | B22: 3440.97 | C22: 3631.73 | D22: 3760.9 | E22: 4177.88 | F22: 4295.79 | G22: 4463.33 | H22: 4890.55 | I22: 5736.22 | J22: 5548.53 | K22: 6169.78
A23: Selling and admin | B23: 4261.78 | C23: 4179.74 | D23: 3954.87 | E23: 4546.39 | F23: 4488.63 | G23: 4236.77 | H23: 4858.38 | I23: 5604.08 | J23: 5312.45 | K23: 5793.29
A24: Other Expenses | B24: 1235.89 | C24: 1169.23 | D24: 1005.98 | E24: 1039.85 | F24: 1225.13 | G24: 1074.39 | H24: 1109.95 | I24: 1308.56 | J24: 1765.97 | K24: 2221.39
A25: Other Income | B25: 1483.11 | C25: 1758.63 | D25: 2239.81 | E25: 2080.44 | F25: 2417.32 | G25: 2576.95 | H25: 1909.72 | I25: 2097.64 | J25: 3330.45 | K25: 17794.88
A26: Depreciation | B26: 1077.4 | C26: 1152.79 | D26: 1236.28 | E26: 1396.61 | F26: 1644.91 | G26: 1645.59 | H26: 1732.41 | I26: 1809.01 | J26: 1518.05 | K26: 1646.32
A27: Interest | B27: 78.13 | C27: 49.03 | D27: 115.01 | E27: 71.4 | F27: 81.38 | G27: 57.97 | H27: 59.99 | I27: 77.77 | J27: 39.11 | K27: 45.06
... A31: Dividend Amount | B31: 6840.12 | C31: 5770.02 | D31: 6285.21 | E31: 7048.7 | F31: 12476.58 | G31: 13231.96 | H31: 14171.8 | I31: 19263.4 | J31: 17166.46 | K31: 17957.73
A40: Quarters
A41: Report Date | B41: 45107 | C41: 45199 | D41: 45291 | E41: 45382 | F41: 45473 | G41: 45565 | H41: 45657 | I41: 45747 | J41: 45838 | K41: 45930
A42: Sales | B42: 17164.46 | C42: 17774.47 | D42: 17195.24 | E42: 17037.8 | F42: 17777.81 | G42: 19990.36 | H42: 18790.17 | I42: 18765 | J42: 21494.79 | K42: 19501.63
A43: Expenses | B43: 10494.39 | C43: 11320.23 | D43: 10985.01 | E43: 10735.73 | F43: 11232.97 | G43: 13438.28 | H43: 12428.27 | I43: 12245.61 | J43: 14678.32 | K43: 12806.94
A44: Other Income | B44: 722.3 | C44: 673.5 | D44: 820.26 | E44: 868 | F44: 771.13 | G44: 690.31 | H44: 803.4 | I44: 15391.28 | J44: 750.97 | K44: 738.84
A45: Depreciation | B45: 442.46 | C45: 453.04 | D45: 384.04 | E45: 385.09 | F45: 403.13 | G45: 416.18 | H45: 415.98 | I45: 411.03 | J45: 422.96 | K45: 434.8
A46: Interest | B46: 9.9 | C46: 9.87 | D46: 11.94 | E46: 10.72 | F46: 9.6 | G46: 14.73 | H46: 9.82 | I46: 10.91 | J46: 16.47 | K46: 20.05
A47: Profit before tax | B47: 6940.01 | C47: 6664.83 | D47: 6634.51 | E47: 6774.26 | F47: 6903.24 | G47: 6811.48 | H47: 6739.5 | I47: 21488.73 | J47: 7128.01 | K47: 6978.68
A48: Tax | B48: 1759.89 | C48: 1700.31 | D48: 1227.99 | E48: 1583.55 | F48: 1726.25 | G48: 1757.05 | H48: 1726.32 | I48: 1680.85 | J48: 1784.6 | K48: 1792.13
A49: Net profit | B49: 5104.93 | C49: 4898.07 | D49: 5335.23 | E49: 5120.55 | F49: 5091.59 | G49: 4992.87 | H49: 4934.8 | I49: 19727.37 | J49: 5244.2 | K49: 5126.11
A50: Operating Profit | B50: 6670.07 | C50: 6454.24 | D50: 6210.23 | E50: 6302.07 | F50: 6544.84 | G50: 6552.08 | H50: 6361.9 | I50: 6519.39 | J50: 6816.47 | K50: 6694.69
A55: BALANCE SHEET
A56: Report Date | B56: 42460 | C56: 42825 | D56: 43190 | E56: 43555 | F56: 43921 | G56: 44286 | H56: 44651 | I56: 45016 | J56: 45382 | K56: 45747
A57: Equity Share Capital | B57: 804.72 | C57: 1214.74 | D57: 1220.43 | E57: 1225.86 | F57: 1229.22 | G57: 1230.88 | H57: 1232.33 | I57: 1242.8 | J57: 1248.47 | K57: 1251.41
A58: Reserves | B58: 41874.8 | C58: 45198.19 | D58: 51289.68 | E58: 57915.01 | F58: 64044.04 | G58: 59116.46 | H58: 61223.24 | I58: 67912.46 | J58: 73258.53 | K58: 68778.64
A59: Borrowings | B59: 83.78 | C59: 45.72 | D59: 35.92 | E59: 13.44 | F59: 277.45 | G59: 270.83 | H59: 249.44 | I59: 306.04 | J59: 303.43 | K59: 284.54
A60: Other Liabilities | B60: 8888.04 | C60: 9439.67 | D60: 11694.85 | E60: 12584.73 | F60: 11760.04 | G60: 13142.59 | H60: 14491.01 | I60: 16369.66 | J60: 16943.54 | K60: 17688.11
A61: Total | B61: 51651.34 | C61: 55898.32 | D61: 64240.88 | E61: 71739.04 | F61: 77310.75 | G61: 73760.76 | H61: 77196.02 | I61: 85830.96 | J61: 91753.97 | K61: 88002.7
...
